<?xml version="1.0" ?>
<!-- 
  Copyright (C) 2020  Rhys Mainwaring

  This program is free software: you can redistribute it and/or modify
  it under the terms of the GNU General Public License as published by
  the Free Software Foundation, either version 3 of the License, or
  (at your option) any later version.

  This program is distributed in the hope that it will be useful,
  but WITHOUT ANY WARRANTY; without even the implied warranty of
  MERCHANTABILITY or FITNESS FOR A PARTICULAR PURPOSE.  See the
  GNU General Public License for more details.

  You should have received a copy of the GNU General Public License
  along with this program.  If not, see <https://www.gnu.org/licenses/>.
-->

<!--  xacro macros for rs750 righ.

 -->
<robot xmlns:xacro="http://ros.org/wiki/xacro">


    <xacro:macro name="rig" params="base_link scale x y z"> 

        <!-- Rough estimates for intertial -->
        <xacro:property name="main_sail_mass" value="${0.100 * scale * scale * scale}" />
        <xacro:property name="main_sail_length" value="${0.200 * scale}" />
        <xacro:property name="main_sail_width" value="${0.006 * scale}" /> 
        <xacro:property name="main_sail_depth" value="${0.900 * scale}" />

        <!-- Rough estimates for intertial -->
        <xacro:property name="fore_sail_mass" value="${0.0500 * scale * scale * scale}" />
        <xacro:property name="fore_sail_length" value="${0.100 * scale}" />
        <xacro:property name="fore_sail_width" value="${0.006 * scale}" /> 
        <xacro:property name="fore_sail_depth" value="${0.700 * scale}" />

        <!-- Mast (visual only) -->
        <link name="mast_link">
            <visual>
                <origin rpy="0 0 0" xyz="0 0 0" />
                <geometry>
                    <mesh filename="package://rs750_description/meshes/rs750_mast.stl" />
                </geometry>
                <material name="black" />
            </visual>
        </link>

        <gazebo reference="mast_link">
            <material>Gazebo/Black</material>
        </gazebo>

        <joint name="mast_joint" type="fixed">
            <origin rpy="0 0 0" xyz="${x} ${y} ${z + 2.09}"/>
            <parent link="${base_link}" />
            <child link="mast_link" />
        </joint>

        <gazebo reference="mast_joint">
        </gazebo>

        <!-- Main sail -->
        <link name="main_sail_link">
            <visual>
                <origin rpy="0 0 0" xyz="0 0 0" />
                <geometry>
                    <mesh filename="package://rs750_description/meshes/rs750_main_sail.stl" />
                </geometry>
                <material name="gray" />
            </visual>

            <collision>
                <origin rpy="0 0 0" xyz="0 0 0" />
                <geometry>
                    <mesh filename="package://rs750_description/meshes/rs750_main_sail.stl" />
                </geometry>
            </collision>
            <xacro:solid_cuboid_inertial 
                rpy="0 0 0" xyz="0 0 0"
                mass="${main_sail_mass}"
                x="${main_sail_length}" y="${main_sail_width}" z="${main_sail_depth}" />
        </link>

        <gazebo reference="main_sail_link">
            <material>Gazebo/GreyTransparent</material>
        </gazebo>

        <joint name="main_sail_joint" type="revolute">
            <origin rpy="0 0 0" xyz="${x - 0.02625} ${y} ${z + 0.291875}"/>
            <axis xyz="0 0 1" />
            <limit 
                lower="${-math_pi_over_2}"
                upper="${math_pi_over_2}"
                effort="1000"
                velocity="1000"
            />
            <parent link="${base_link}" />
            <child link="main_sail_link" />
        </joint>

        <transmission name="main_sail_transmission" >
            <type>transmission_interface/SimpleTransmission</type>
            <actuator name="main_sail_actuator">
                <mechanicalReduction>1</mechanicalReduction>
            </actuator>
            <joint name="main_sail_joint">
                <hardwareInterface>hardware_interface/PositionJointInterface</hardwareInterface>
            </joint>
        </transmission>

        <gazebo reference="main_sail_joint">
            <provideFeedback>true</provideFeedback>
        </gazebo>

        <!-- Fore sail -->
        <link name="fore_sail_link">
            <visual>
                <origin rpy="0 0 0" xyz="0 0 0" />
                <geometry>
                    <mesh filename="package://rs750_description/meshes/rs750_fore_sail.stl" />
                </geometry>
                <material name="gray" />
            </visual>

            <collision>
                <origin rpy="0 0 0" xyz="0 0 0" />
                <geometry>
                    <mesh filename="package://rs750_description/meshes/rs750_fore_sail.stl" />
                </geometry>
            </collision>
            <xacro:solid_cuboid_inertial 
                rpy="0 0 0" xyz="0 0 0"
                mass="${fore_sail_mass}"
                x="${fore_sail_length}" y="${fore_sail_width}" z="${fore_sail_depth}" />
        </link>

        <gazebo reference="fore_sail_link">
            <material>Gazebo/GreyTransparent</material>
        </gazebo>

        <joint name="fore_sail_joint" type="revolute">
            <origin rpy="0 0 0" xyz="${x + 1.03125} ${y} ${z + 0.235625}"/>
            <axis xyz="-0.271652766 0 0.962395332" />
            <limit 
                lower="${-math_pi_over_2}"
                upper="${math_pi_over_2}"
                effort="1000"
                velocity="1000"
            />
            <parent link="${base_link}" />
            <child link="fore_sail_link" />
        </joint>

        <transmission name="fore_sail_transmission" >
            <type>transmission_interface/SimpleTransmission</type>
            <actuator name="fore_sail_actuator">
                <mechanicalReduction>1</mechanicalReduction>
            </actuator>
            <joint name="fore_sail_joint">
                <hardwareInterface>hardware_interface/PositionJointInterface</hardwareInterface>
            </joint>
        </transmission>

        <gazebo reference="fore_sail_joint">
            <provideFeedback>true</provideFeedback>
        </gazebo>
    </xacro:macro>

</robot>
