<?xml version="1.0" ?>
<!-- 
    Software License Agreement (BSD-3-Clause)

    Copyright (c) 2020 Rhys Mainwaring
    All rights reserved.

    Redistribution and use in source and binary forms, with or without
    modification, are permitted provided that the following conditions
    are met:

    1.  Redistributions of source code must retain the above copyright
        notice, this list of conditions and the following disclaimer.

    2.  Redistributions in binary form must reproduce the above
        copyright notice, this list of conditions and the following
        disclaimer in the documentation and/or other materials provided
        with the distribution.

    3.  Neither the name of the copyright holder nor the names of its
        contributors may be used to endorse or promote products derived
        from this software without specific prior written permission.

    THIS SOFTWARE IS PROVIDED BY THE COPYRIGHT HOLDERS AND CONTRIBUTORS
    "AS IS" AND ANY EXPRESS OR IMPLIED WARRANTIES, INCLUDING, BUT NOT
    LIMITED TO, THE IMPLIED WARRANTIES OF MERCHANTABILITY AND FITNESS
    FOR A PARTICULAR PURPOSE ARE DISCLAIMED. IN NO EVENT SHALL THE
    COPYRIGHT HOLDER OR CONTRIBUTORS BE LIABLE FOR ANY DIRECT, INDIRECT,
    INCIDENTAL, SPECIAL, EXEMPLARY, OR CONSEQUENTIAL DAMAGES (INCLUDING,
    BUT NOT LIMITED TO, PROCUREMENT OF SUBSTITUTE GOODS OR SERVICES;
    LOSS OF USE, DATA, OR PROFITS; OR BUSINESS INTERRUPTION) HOWEVER
    CAUSED AND ON ANY THEORY OF LIABILITY, WHETHER IN CONTRACT, STRICT
    LIABILITY, OR TORT (INCLUDING NEGLIGENCE OR OTHERWISE) ARISING IN
    ANY WAY OUT OF THE USE OF THIS SOFTWARE, EVEN IF ADVISED OF THE
    POSSIBILITY OF SUCH DAMAGE.
-->

<!--  xacro macros for rs750 righ.

 -->
<robot xmlns:xacro="http://ros.org/wiki/xacro">
    <xacro:macro name="rig" params="base_link x y z"> 

        <!-- Mast (visual only) -->
        <link name="mast_link">
            <visual>
                <origin rpy="0 0 0" xyz="0 0 0" />
                <geometry>
                    <mesh filename="package://rs750_description/meshes/rs750_mast.stl" />
                </geometry>
                <material name="black" />
            </visual>
        </link>

        <gazebo reference="mast_link">
            <material>Gazebo/Black</material>
        </gazebo>

        <joint name="mast_joint" type="fixed">
            <origin rpy="0 0 0" xyz="${x} ${y} ${z + 2.09}"/>
            <parent link="${base_link}" />
            <child link="mast_link" />
        </joint>

        <gazebo reference="mast_joint">
        </gazebo>

        <!-- Main sail -->
        <link name="main_sail_link">
            <visual>
                <origin rpy="0 0 0" xyz="0 0 0" />
                <geometry>
                    <mesh filename="package://rs750_description/meshes/rs750_main_sail.stl" />
                </geometry>
                <material name="gray" />
            </visual>

            <collision>
                <origin rpy="0 0 0" xyz="0 0 0" />
                <geometry>
                    <mesh filename="package://rs750_description/meshes/rs750_main_sail.stl" />
                </geometry>
            </collision>
            <xacro:solid_cuboid_inertial 
                rpy="0 0 0" xyz="0 0 0"
                mass="${main_sail_mass}"
                x="${main_sail_length}" y="${main_sail_width}" z="${main_sail_depth}" />
        </link>

        <gazebo reference="main_sail_link">
            <material>Gazebo/GreyTransparent</material>
        </gazebo>

        <joint name="main_sail_joint" type="revolute">
            <origin rpy="0 0 0" xyz="${x - 0.02625} ${y} ${z + 0.291875}"/>
            <axis xyz="0 0 1" />
            <limit 
                lower="${-math_pi_over_2}"
                upper="${math_pi_over_2}"
                effort="1000"
                velocity="1000"
            />
            <parent link="${base_link}" />
            <child link="main_sail_link" />
        </joint>

        <transmission name="main_sail_transmission" >
            <type>transmission_interface/SimpleTransmission</type>
            <actuator name="main_sail_actuator">
                <mechanicalReduction>1</mechanicalReduction>
            </actuator>
            <joint name="main_sail_joint">
                <hardwareInterface>hardware_interface/PositionJointInterface</hardwareInterface>
            </joint>
        </transmission>

        <gazebo reference="main_sail_joint">
            <provideFeedback>true</provideFeedback>
        </gazebo>

        <!-- Fore sail -->
        <link name="fore_sail_link">
            <visual>
                <origin rpy="0 0 0" xyz="0 0 0" />
                <geometry>
                    <mesh filename="package://rs750_description/meshes/rs750_fore_sail.stl" />
                </geometry>
                <material name="gray" />
            </visual>

            <collision>
                <origin rpy="0 0 0" xyz="0 0 0" />
                <geometry>
                    <mesh filename="package://rs750_description/meshes/rs750_fore_sail.stl" />
                </geometry>
            </collision>
            <xacro:solid_cuboid_inertial 
                rpy="0 0 0" xyz="0 0 0"
                mass="${fore_sail_mass}"
                x="${fore_sail_length}" y="${fore_sail_width}" z="${fore_sail_depth}" />
        </link>

        <gazebo reference="fore_sail_link">
            <material>Gazebo/GreyTransparent</material>
        </gazebo>

        <joint name="fore_sail_joint" type="revolute">
            <origin rpy="0 0 0" xyz="${x + 1.03125} ${y} ${z + 0.235625}"/>
            <axis xyz="-0.271652766 0 0.962395332" />
            <limit 
                lower="${-math_pi_over_2}"
                upper="${math_pi_over_2}"
                effort="1000"
                velocity="1000"
            />
            <parent link="${base_link}" />
            <child link="fore_sail_link" />
        </joint>

        <transmission name="fore_sail_transmission" >
            <type>transmission_interface/SimpleTransmission</type>
            <actuator name="fore_sail_actuator">
                <mechanicalReduction>1</mechanicalReduction>
            </actuator>
            <joint name="fore_sail_joint">
                <hardwareInterface>hardware_interface/PositionJointInterface</hardwareInterface>
            </joint>
        </transmission>

        <gazebo reference="fore_sail_joint">
            <provideFeedback>true</provideFeedback>
        </gazebo>
    </xacro:macro>

</robot>
